Workbook

Sheet Note for Barry
A2: Notes | B2: Hi Barry, this is the companion file for the presentation, in case you want to take a look under the hood. Different colored tabs highlight each component. There is a key below to help you navigate. All VIN/Dealer/Call Center data is simulated, generated from GPT 4.6, but all the calculations are manual. The AI/ML (XG Boost) component was completed with a Python script from Claude to help speed things up (over 200 lines of code!).
B3: Inside you'll have two outputs, as mentioned. The 100 sample VINs make for a statistically robust model, but the XG Boost component would need a significantly larger amount (5000+ VINs) to train on to be more accurate in its predictions.
B4: Please feel free to give me a call if you have any questions on anything. Thank you.
A6: KEY
A7: Red Tab | B7: Ready for operational use with risk framework summary, dashboard
A8: Yellow Tab | B8: Master output sheet with unified reporting and risk scoring. Columns P-AB provide all calculations and a final risk score by VIN
A9: Navy Tab | B9: Underlying reports from business function groups (simulated)
A10: Light Blue Tab | B10: Regression data, muliplier tables derived from likelihood (based on regression results) and a risk scoring band to classify risk level. Essentially, statistical proof of significance for all risk drivers.
A11: Green Tab | B11: Python XG Boost prototype script output based on 10 features (risk drivers).

Sheet Model Framework
A1: CEO Escalation Risk Model
A3: Purpose | B3: Reduce CEO/Executive escalations from customers via email, mail, or social media.
A5: Task | B5: Develop an operational risk framework that enables field teams to proactively identify VINs with the highest likelihood of executive escalation.
A7: Methodology | B7: Consolidated VIN-level operational data across dealer service operations (Aged RO tracking, NPS, training, warranty), customer assistance center interactions, and executive escalation reporting into a unified risk dataset.
B8: Applied regression analysis and a second layer of gradient boosting (Extreme Gradient (XG) Boost-style modeling) to identify the strongest operational drivers associated with executive escalation behavior and predictive escalation likelihood.
B9: Structured the framework into Idiosyncratic Risk, Systemic Risk, and Gamma / Time Trust Decay components to create a bounded VIN-level prioritization model for proactive field intervention.
A11: Model Structure
A12: Idiosyncratic Risk | B12: (0.35×Mobility (Loaner Coverage) + 0.65×Repeat Repair) × (0.6×Missed Callbacks + 0.4×Agent Transfers)
A13: Systemic Risk | B13: 0.35×Dealer NPS + 0.45×Dealer Repeat Repair % + 0.2×Training Deficiency
A14: Time Trust Decay | B14: Describes acceleration of customer trust decay by illustrating a non-liner relationship between all defined risk factors. As repair delay increases, exposure to Lemon Law and repurchase likelihood increases.
A15: Total Risk | B15: Systemic Risk (Servicing Dealer) x Idiosyncratic Risk x Time Trust Decay Factor (Gamma)
A17: Key Insights | B17: Executive escalation risk was most strongly associated with compounded operational friction, particularly missed callbacks, repeated agent transfers, repeat repairs, and prolonged repair exposure over time.
B18: Dealer operational maturity variables such as technician training completion, dealer repeat repair performance, and NPS demonstrated meaningful influence on escalation likelihood, reinforcing the importance of systemic dealer capability.
B19: Predictive modeling demonstrated the ability to directionally identify high-risk VIN populations for proactive field intervention, enabling escalation prevention through earlier operational prioritization and communication ownership.
A21: Limitations | B21: This is a predictive scoring tool, not a causality claim. It scores VIN-level escalation risk from customer friction, dealer environment, and time exposure.
A23: Opportunities | B23: XG Boost would benefit from larger dataset to train machine learning model.
A25: Call to Action | B25: By reducing information asymmetry across dealer operations, customer assistance, and field leadership teams, the framework enables proactive, data-driven collaboration around escalation prevention and customer retention.

Sheet Risk Framework
A1: Time Trust Decay Weighing & Convexity Explained
A21: Time Decay | B21: Risk Acceleration | C21: Likelihood Factor
A22: Days Down | B22: Risk Behavior | C22: Multiplier
A23: 0-7 | B23: Normal service friction | C23: 1
A24: 8-14 | B24: Customer patience starts decaying | C24: 1.1
A25: 15-21 | B25: Escalation probability rises | C25: 1.25
A26: 22-29 | B26: Trust breakdown accelerates | C26: 1.5
A27: 30+ | B27: Risk compounds rapidly | C27: 2
A30: Sample Risk Driver
A52: Risk Driver | B52: Idiosyncratic Risk Weighting: 0.30 | C52: Likelihood Factor | D52: Time Trust Decay Factor
A53: Repeat Repair | B53: Risk Behavior | C53: Base Risk | D53: 0-7 | E53: 8-14 | F53: 15-21 | G53: 22-29 | H53: 30+
A54: 0-1 | B54: Normal service friction | C54: 1 | D54: =C54*$C$23 -> 1 | E54: =C54*$C$24 -> 1.1 | F54: =C54*$C$25 -> 1.25 | G54: =C54*$C$26 -> 1.5 | H54: =D54*$C$27 -> 2
A55: 2 | B55: Customer inconvenience escalates | C55: 1.15 | D55: =C55*$C$23 -> 1.15 | E55: =C55*$C$24 -> 1.265 | F55: =C55*$C$25 -> 1.4375 | G55: =C55*$C$26 -> 1.725 | H55: =D55*$C$27 -> 2.3
A56: 3 | B56: Customer begins researrching non-factory resolution | C56: 1.3 | D56: =C56*$C$23 -> 1.3 | E56: =C56*$C$24 -> 1.43 | F56: =C56*$C$25 -> 1.625 | G56: =C56*$C$26 -> 1.95 | H56: =D56*$C$27 -> 2.6
A57: 4 | B57: Repurchase/legal risk expands | C57: 1.45 | D57: =C57*$C$23 -> 1.45 | E57: =C57*$C$24 -> 1.595 | F57: =C57*$C$25 -> 1.8125 | G57: =C57*$C$26 -> 2.175 | H57: =D57*$C$27 -> 2.9
A59: Sample VIN
A65: Risk Driver Layers | C65: Multiplier | D65: Output
A66: Mobility | C66: 1.6 | D66: 1.6
A67: Repeat Repair | C67: 1.3 | D67: 1.3
A68: Missed Callbacks | C68: 1.75 | D68: 1.75
A69: Call Transfers | C69: 3.25 | D69: 3.25
A70: Idiosyncratic Risk | C70: ((0.35×1.60)+(0.65×1.30)) × ((0.60×1.75)+(0.40×3.25)) | D70: 3.3
A71: Dealer NPS Multiplier | C71: 1.25 | D71: 1.25
A72: Dealer RR Multiplier | C72: 1.1 | D72: 1.1
A73: Training Multiplier | C73: 1.3 | D73: 1.3
A74: Systemic Risk | C74: (0.45×1.25)+(0.35×1.10)+(0.20×1.30) | D74: 1.19
A75: Time Decay / Gamma | C75: 30 Days Down | D75: 2
A76: Final Risk Score | C76: 3.30 × 1.19 × 2.00 | D76: 7.85

Sheet Unified VIN Risk Scoring
A1: VIN | B1: CEO Escalated | C1: Dealer BAC | D1: Dealer Name | E1: Area Manager | F1: RO Open Date | G1: Days Down | H1: Repeat Repairs | I1: Mobility Status | J1: Dealer NPS | K1: Dealer Repeat Repair % | L1: Dealer Training Completion % | M1: Agent Transfers | N1: Missed Callbacks | O1: CAC Contacts | P1: Case Reopens | Q1: Mobility Multiplier | R1: Repeat Repair Multiplier | S1: Missed Callback Multiplier | T1: Agent Transfer Multiplier | U1: Dealer NPS Multiplier | V1: Dealer RR Multiplier | W1: Training Multiplier | X1: Time Decay | Y1: Idiosyncratic Risk | Z1: Systemic Risk | AA1: Total Risk Score | AB1: Capped Risk Score | AC1: Risk Band
A2: 98NHIHHW64RX2DX62 | B2: 1 | C2: 81773 | D2: =_xlfn.XLOOKUP(C2,'Dealer Operations'!B:B,'Dealer Operations'!C:C,"Not Found") -> Hyundai San Diego | E2: =_xlfn.XLOOKUP(C3,'Dealer Operations'!B:B,'Dealer Operations'!D:D,"Not Found") -> Shohei Ohtani | F2: =_xlfn.XLOOKUP(A2,'Dealer Operations'!A:A,'Dealer Operations'!E:E,"Not Found") -> 46111 | G2: 44 | H2: 3 | I2: No Loaner Coverage | J2: =_xlfn.XLOOKUP(C2,'Dealer Operations'!B:B,'Dealer Operations'!I:I,"Not Found") -> 68 | K2: =_xlfn.XLOOKUP(C2,'Dealer Operations'!B:B,'Dealer Operations'!J:J,"Not Found") -> 9.3 | L2: =_xlfn.XLOOKUP(C2,'Dealer Operations'!B:B,'Dealer Operations'!K:K,"Not Found") -> 55 | M2: 8 | N2: 5 | O2: 5 | P2: 4 | Q2: =IF(I2="Loaner Covered",0.85,IF(I2="External Rental",1.3,IF(I2="No Loaner Coverage",1.6,1))) -> 1.6 | R2: =IF(H2<=1,1,IF(H2=2,1.15,IF(H2=3,1.3,1.45))) -> 1.3 | S2: =IF(N2=0,1,IF(N2=1,1.75,IF(N2=2,2.5,IF(N2=3,3.25,4)))) -> 4 | T2: =IF(M2<=1,1,IF(M2<=3,1.75,IF(M2<=5,2.5,IF(M2<=7,3.25,3.75)))) -> 3.75 | U2: =IF(J2>=85,1,IF(J2>=75,1.1,IF(J2>=65,1.25,IF(J2>=55,1.35,1.45)))) -> 1.25 | V2: =IF(K2<=5,1,IF(K2<=10,1.1,IF(K2<=15,1.3,1.5))) -> 1.1 | W2: =IF(L2>=95,1,IF(L2>=85,1.1,IF(L2>=75,1.2,IF(L2>=65,1.3,1.4)))) -> 1.4 | X2: =IF(G2<=7,1,IF(G2<=14,1.1,IF(G2<=21,1.25,IF(G2<=29,1.5,2)))) -> 2 | Y2: =((0.35*Q2)+(0.65*R2))*((0.6*S2)+(0.4*T2)) -> 5.4795 | Z2: =(0.35*U2)+(0.45*V2)+(0.2*W2) -> 1.2125 | AA2: =Y2*Z2*X2 -> 13.287788 | AB2: =MIN(AA2,15) -> 13.287788 | AC2: =IF(AB2<3,"Low operational exposure",IF(AB2<6,"Moderate friction",IF(AB2<10,"High escalation risk",IF(AB2<12,"Severe exposure","Critical / Executive intervention")))) -> Critical / Executive intervention
A3: 7BUBE3U7QANV79ROD | B3: 1 | C3: 66520 | D3: =_xlfn.XLOOKUP(C3,'Dealer Operations'!B:B,'Dealer Operations'!C:C,"Not Found") -> Hyundai Santa Monica | E3: =_xlfn.XLOOKUP(C4,'Dealer Operations'!B:B,'Dealer Operations'!D:D,"Not Found") -> Fred Mercury | F3: =_xlfn.XLOOKUP(A3,'Dealer Operations'!A:A,'Dealer Operations'!E:E,"Not Found") -> 46120 | G3: 35 | H3: 3 | I3: External Rental | J3: =_xlfn.XLOOKUP(C3,'Dealer Operations'!B:B,'Dealer Operations'!I:I,"Not Found") -> 82 | K3: =_xlfn.XLOOKUP(C3,'Dealer Operations'!B:B,'Dealer Operations'!J:J,"Not Found") -> 10.1 | L3: =_xlfn.XLOOKUP(C3,'Dealer Operations'!B:B,'Dealer Operations'!K:K,"Not Found") -> 56 | M3: 9 | N3: 5 | O3: 6 | P3: 0 | Q3: =IF(I3="Loaner Covered",0.85,IF(I3="External Rental",1.3,IF(I3="No Loaner Coverage",1.6,1))) -> 1.3 | R3: =IF(H3<=1,1,IF(H3=2,1.15,IF(H3=3,1.3,1.45))) -> 1.3 | S3: =IF(N3=0,1,IF(N3=1,1.75,IF(N3=2,2.5,IF(N3=3,3.25,4)))) -> 4 | T3: =IF(M3<=1,1,IF(M3<=3,1.75,IF(M3<=5,2.5,IF(M3<=7,3.25,3.75)))) -> 3.75 | U3: =IF(J3>=85,1,IF(J3>=75,1.1,IF(J3>=65,1.25,IF(J3>=55,1.35,1.45)))) -> 1.1 | V3: =IF(K3<=5,1,IF(K3<=10,1.1,IF(K3<=15,1.3,1.5))) -> 1.3 | W3: =IF(L3>=95,1,IF(L3>=85,1.1,IF(L3>=75,1.2,IF(L3>=65,1.3,1.4)))) -> 1.4 | X3: =IF(G3<=7,1,IF(G3<=14,1.1,IF(G3<=21,1.25,IF(G3<=29,1.5,2)))) -> 2 | Y3: =((0.35*Q3)+(0.65*R3))*((0.6*S3)+(0.4*T3)) -> 5.07 | Z3: =(0.35*U3)+(0.45*V3)+(0.2*W3) -> 1.25 | AA3: =Y3*Z3*X3 -> 12.675 | AB3: =MIN(AA3,15) -> 12.675 | AC3: =IF(AB3<3,"Low operational exposure",IF(AB3<6,"Moderate friction",IF(AB3<10,"High escalation risk",IF(AB3<12,"Severe exposure","Critical / Executive intervention")))) -> Critical / Executive intervention
A4: MT7JESIDFBHLK1KSG | B4: 1 | C4: 44117 | D4: =_xlfn.XLOOKUP(C4,'Dealer Operations'!B:B,'Dealer Operations'!C:C,"Not Found") -> Desert Hyundai | E4: =_xlfn.XLOOKUP(C5,'Dealer Operations'!B:B,'Dealer Operations'!D:D,"Not Found") -> Fred Mercury | F4: =_xlfn.XLOOKUP(A4,'Dealer Operations'!A:A,'Dealer Operations'!E:E,"Not Found") -> 46113 | G4: 42 | H4: 5 | I4: No Loaner Coverage | J4: =_xlfn.XLOOKUP(C4,'Dealer Operations'!B:B,'Dealer Operations'!I:I,"Not Found") -> 58 | K4: =_xlfn.XLOOKUP(C4,'Dealer Operations'!B:B,'Dealer Operations'!J:J,"Not Found") -> 10.5 | L4: =_xlfn.XLOOKUP(C4,'Dealer Operations'!B:B,'Dealer Operations'!K:K,"Not Found") -> 49 | M4: 3 | N4: 7 | O4: 10 | P4: 2 | Q4: =IF(I4="Loaner Covered",0.85,IF(I4="External Rental",1.3,IF(I4="No Loaner Coverage",1.6,1))) -> 1.6 | R4: =IF(H4<=1,1,IF(H4=2,1.15,IF(H4=3,1.3,1.45))) -> 1.45 | S4: =IF(N4=0,1,IF(N4=1,1.75,IF(N4=2,2.5,IF(N4=3,3.25,4)))) -> 4 | T4: =IF(M4<=1,1,IF(M4<=3,1.75,IF(M4<=5,2.5,IF(M4<=7,3.25,3.75)))) -> 1.75 | U4: =IF(J4>=85,1,IF(J4>=75,1.1,IF(J4>=65,1.25,IF(J4>=55,1.35,1.45)))) -> 1.35 | V4: =IF(K4<=5,1,IF(K4<=10,1.1,IF(K4<=15,1.3,1.5))) -> 1.3 | W4: =IF(L4>=95,1,IF(L4>=85,1.1,IF(L4>=75,1.2,IF(L4>=65,1.3,1.4)))) -> 1.4 | X4: =IF(G4<=7,1,IF(G4<=14,1.1,IF(G4<=21,1.25,IF(G4<=29,1.5,2)))) -> 2 | Y4: =((0.35*Q4)+(0.65*R4))*((0.6*S4)+(0.4*T4)) -> 4.65775 | Z4: =(0.35*U4)+(0.45*V4)+(0.2*W4) -> 1.3375 | AA4: =Y4*Z4*X4 -> 12.459481 | AB4: =MIN(AA4,15) -> 12.459481 | AC4: =IF(AB4<3,"Low operational exposure",IF(AB4<6,"Moderate friction",IF(AB4<10,"High escalation risk",IF(AB4<12,"Severe exposure","Critical / Executive intervention")))) -> Critical / Executive intervention
A5: JXKUOGFH6RH69QFGD | B5: 1 | C5: 77841 | D5: =_xlfn.XLOOKUP(C5,'Dealer Operations'!B:B,'Dealer Operations'!C:C,"Not Found") -> Victorville Hyundai | E5: =_xlfn.XLOOKUP(C6,'Dealer Operations'!B:B,'Dealer Operations'!D:D,"Not Found") -> Fred Mercury | F5: =_xlfn.XLOOKUP(A5,'Dealer Operations'!A:A,'Dealer Operations'!E:E,"Not Found") -> 46132 | G5: 23 | H5: 3 | I5: External Rental | J5: =_xlfn.XLOOKUP(C5,'Dealer Operations'!B:B,'Dealer Operations'!I:I,"Not Found") -> 86 | K5: =_xlfn.XLOOKUP(C5,'Dealer Operations'!B:B,'Dealer Operations'!J:J,"Not Found") -> 8 | L5: =_xlfn.XLOOKUP(C5,'Dealer Operations'!B:B,'Dealer Operations'!K:K,"Not Found") -> 80 | M5: 9 | N5: 4 | O5: 5 | P5: 1 | Q5: =IF(I5="Loaner Covered",0.85,IF(I5="External Rental",1.3,IF(I5="No Loaner Coverage",1.6,1))) -> 1.3 | R5: =IF(H5<=1,1,IF(H5=2,1.15,IF(H5=3,1.3,1.45))) -> 1.3 | S5: =IF(N5=0,1,IF(N5=1,1.75,IF(N5=2,2.5,IF(N5=3,3.25,4)))) -> 4 | T5: =IF(M5<=1,1,IF(M5<=3,1.75,IF(M5<=5,2.5,IF(M5<=7,3.25,3.75)))) -> 3.75 | U5: =IF(J5>=85,1,IF(J5>=75,1.1,IF(J5>=65,1.25,IF(J5>=55,1.35,1.45)))) -> 1 | V5: =IF(K5<=5,1,IF(K5<=10,1.1,IF(K5<=15,1.3,1.5))) -> 1.1 | W5: =IF(L5>=95,1,IF(L5>=85,1.1,IF(L5>=75,1.2,IF(L5>=65,1.3,1.4)))) -> 1.2 | X5: =IF(G5<=7,1,IF(G5<=14,1.1,IF(G5<=21,1.25,IF(G5<=29,1.5,2)))) -> 1.5 | Y5: =((0.35*Q5)+(0.65*R5))*((0.6*S5)+(0.4*T5)) -> 5.07 | Z5: =(0.35*U5)+(0.45*V5)+(0.2*W5) -> 1.085 | AA5: =Y5*Z5*X5 -> 8.251425 | AB5: =MIN(AA5,15) -> 8.251425 | AC5: =IF(AB5<3,"Low operational exposure",IF(AB5<6,"Moderate friction",IF(AB5<10,"High escalation risk",IF(AB5<12,"Severe exposure","Critical / Executive intervention")))) -> High escalation risk
A6: UTZSX3SO8HYO1E9MC | B6: 1 | C6: 11425 | D6: =_xlfn.XLOOKUP(C6,'Dealer Operations'!B:B,'Dealer Operations'!C:C,"Not Found") -> Keyes Hyundai | E6: =_xlfn.XLOOKUP(C7,'Dealer Operations'!B:B,'Dealer Operations'!D:D,"Not Found") -> Fred Mercury | F6: =_xlfn.XLOOKUP(A6,'Dealer Operations'!A:A,'Dealer Operations'!E:E,"Not Found") -> 46128 | G6: 27 | H6: 5 | I6: No Loaner Coverage | J6: =_xlfn.XLOOKUP(C6,'Dealer Operations'!B:B,'Dealer Operations'!I:I,"Not Found") -> 86 | K6: =_xlfn.XLOOKUP(C6,'Dealer Operations'!B:B,'Dealer Operations'!J:J,"Not Found") -> 6.8 | L6: =_xlfn.XLOOKUP(C6,'Dealer Operations'!B:B,'Dealer Operations'!K:K,"Not Found") -> 89 | M6: 10 | N6: 2 | O6: 9 | P6: 1 | Q6: =IF(I6="Loaner Covered",0.85,IF(I6="External Rental",1.3,IF(I6="No Loaner Coverage",1.6,1))) -> 1.6 | R6: =IF(H6<=1,1,IF(H6=2,1.15,IF(H6=3,1.3,1.45))) -> 1.45 | S6: =IF(N6=0,1,IF(N6=1,1.75,IF(N6=2,2.5,IF(N6=3,3.25,4)))) -> 2.5 | T6: =IF(M6<=1,1,IF(M6<=3,1.75,IF(M6<=5,2.5,IF(M6<=7,3.25,3.75)))) -> 3.75 | U6: =IF(J6>=85,1,IF(J6>=75,1.1,IF(J6>=65,1.25,IF(J6>=55,1.35,1.45)))) -> 1 | V6: =IF(K6<=5,1,IF(K6<=10,1.1,IF(K6<=15,1.3,1.5))) -> 1.1 | W6: =IF(L6>=95,1,IF(L6>=85,1.1,IF(L6>=75,1.2,IF(L6>=65,1.3,1.4)))) -> 1.1 | X6: =IF(G6<=7,1,IF(G6<=14,1.1,IF(G6<=21,1.25,IF(G6<=29,1.5,2)))) -> 1.5 | Y6: =((0.35*Q6)+(0.65*R6))*((0.6*S6)+(0.4*T6)) -> 4.5075 | Z6: =(0.35*U6)+(0.45*V6)+(0.2*W6) -> 1.065 | AA6: =Y6*Z6*X6 -> 7.2007313 | AB6: =MIN(AA6,15) -> 7.2007313 | AC6: =IF(AB6<3,"Low operational exposure",IF(AB6<6,"Moderate friction",IF(AB6<10,"High escalation risk",IF(AB6<12,"Severe exposure","Critical / Executive intervention")))) -> High escalation risk
A7: K8RGIPX8FOH9FBCO6 | B7: 1 | C7: 11425 | D7: =_xlfn.XLOOKUP(C7,'Dealer Operations'!B:B,'Dealer Operations'!C:C,"Not Found") -> Keyes Hyundai | E7: =_xlfn.XLOOKUP(C8,'Dealer Operations'!B:B,'Dealer Operations'!D:D,"Not Found") -> Shohei Ohtani | F7: =_xlfn.XLOOKUP(A7,'Dealer Operations'!A:A,'Dealer Operations'!E:E,"Not Found") -> 46108 | G7: 47 | H7: 0 | I7: External Rental | J7: =_xlfn.XLOOKUP(C7,'Dealer Operations'!B:B,'Dealer Operations'!I:I,"Not Found") -> 86 | K7: =_xlfn.XLOOKUP(C7,'Dealer Operations'!B:B,'Dealer Operations'!J:J,"Not Found") -> 6.8 | L7: =_xlfn.XLOOKUP(C7,'Dealer Operations'!B:B,'Dealer Operations'!K:K,"Not Found") -> 89 | M7: 6 | N7: 7 | O7: 6 | P7: 0 | Q7: =IF(I7="Loaner Covered",0.85,IF(I7="External Rental",1.3,IF(I7="No Loaner Coverage",1.6,1))) -> 1.3 | R7: =IF(H7<=1,1,IF(H7=2,1.15,IF(H7=3,1.3,1.45))) -> 1 | S7: =IF(N7=0,1,IF(N7=1,1.75,IF(N7=2,2.5,IF(N7=3,3.25,4)))) -> 4 | T7: =IF(M7<=1,1,IF(M7<=3,1.75,IF(M7<=5,2.5,IF(M7<=7,3.25,3.75)))) -> 3.25 | U7: =IF(J7>=85,1,IF(J7>=75,1.1,IF(J7>=65,1.25,IF(J7>=55,1.35,1.45)))) -> 1 | V7: =IF(K7<=5,1,IF(K7<=10,1.1,IF(K7<=15,1.3,1.5))) -> 1.1 | W7: =IF(L7>=95,1,IF(L7>=85,1.1,IF(L7>=75,1.2,IF(L7>=65,1.3,1.4)))) -> 1.1 | X7: =IF(G7<=7,1,IF(G7<=14,1.1,IF(G7<=21,1.25,IF(G7<=29,1.5,2)))) -> 2 | Y7: =((0.35*Q7)+(0.65*R7))*((0.6*S7)+(0.4*T7)) -> 4.0885 | Z7: =(0.35*U7)+(0.45*V7)+(0.2*W7) -> 1.065 | AA7: =Y7*Z7*X7 -> 8.708505 | AB7: =MIN(AA7,15) -> 8.708505 | AC7: =IF(AB7<3,"Low operational exposure",IF(AB7<6,"Moderate friction",IF(AB7<10,"High escalation risk",IF(AB7<12,"Severe exposure","Critical / Executive intervention")))) -> High escalation risk
A8: 13WQUI8MW33QKTE4M | B8: 1 | C8: 81773 | D8: =_xlfn.XLOOKUP(C8,'Dealer Operations'!B:B,'Dealer Operations'!C:C,"Not Found") -> Hyundai San Diego | E8: =_xlfn.XLOOKUP(C9,'Dealer Operations'!B:B,'Dealer Operations'!D:D,"Not Found") -> Fred Mercury | F8: =_xlfn.XLOOKUP(A8,'Dealer Operations'!A:A,'Dealer Operations'!E:E,"Not Found") -> 46120 | G8: 35 | H8: 5 | I8: External Rental | J8: =_xlfn.XLOOKUP(C8,'Dealer Operations'!B:B,'Dealer Operations'!I:I,"Not Found") -> 68 | K8: =_xlfn.XLOOKUP(C8,'Dealer Operations'!B:B,'Dealer Operations'!J:J,"Not Found") -> 9.3 | L8: =_xlfn.XLOOKUP(C8,'Dealer Operations'!B:B,'Dealer Operations'!K:K,"Not Found") -> 55 | M8: 10 | N8: 1 | O8: 6 | P8: 2 | Q8: =IF(I8="Loaner Covered",0.85,IF(I8="External Rental",1.3,IF(I8="No Loaner Coverage",1.6,1))) -> 1.3 | R8: =IF(H8<=1,1,IF(H8=2,1.15,IF(H8=3,1.3,1.45))) -> 1.45 | S8: =IF(N8=0,1,IF(N8=1,1.75,IF(N8=2,2.5,IF(N8=3,3.25,4)))) -> 1.75 | T8: =IF(M8<=1,1,IF(M8<=3,1.75,IF(M8<=5,2.5,IF(M8<=7,3.25,3.75)))) -> 3.75 | U8: =IF(J8>=85,1,IF(J8>=75,1.1,IF(J8>=65,1.25,IF(J8>=55,1.35,1.45)))) -> 1.25 | V8: =IF(K8<=5,1,IF(K8<=10,1.1,IF(K8<=15,1.3,1.5))) -> 1.1 | W8: =IF(L8>=95,1,IF(L8>=85,1.1,IF(L8>=75,1.2,IF(L8>=65,1.3,1.4)))) -> 1.4 | X8: =IF(G8<=7,1,IF(G8<=14,1.1,IF(G8<=21,1.25,IF(G8<=29,1.5,2)))) -> 2 | Y8: =((0.35*Q8)+(0.65*R8))*((0.6*S8)+(0.4*T8)) -> 3.563625 | Z8: =(0.35*U8)+(0.45*V8)+(0.2*W8) -> 1.2125 | AA8: =Y8*Z8*X8 -> 8.6417906 | AB8: =MIN(AA8,15) -> 8.6417906 | AC8: =IF(AB8<3,"Low operational exposure",IF(AB8<6,"Moderate friction",IF(AB8<10,"High escalation risk",IF(AB8<12,"Severe exposure","Critical / Executive intervention")))) -> High escalation risk
A9: OL9F0XB46W03FSS42 | B9: 1 | C9: 11425 | D9: =_xlfn.XLOOKUP(C9,'Dealer Operations'!B:B,'Dealer Operations'!C:C,"Not Found") -> Keyes Hyundai | E9: =_xlfn.XLOOKUP(C10,'Dealer Operations'!B:B,'Dealer Operations'!D:D,"Not Found") -> Fred Mercury | F9: =_xlfn.XLOOKUP(A9,'Dealer Operations'!A:A,'Dealer Operations'!E:E,"Not Found") -> 46130 | G9: 25 | H9: 5 | I9: Loaner Covered | J9: =_xlfn.XLOOKUP(C9,'Dealer Operations'!B:B,'Dealer Operations'!I:I,"Not Found") -> 86 | K9: =_xlfn.XLOOKUP(C9,'Dealer Operations'!B:B,'Dealer Operations'!J:J,"Not Found") -> 6.8 | L9: =_xlfn.XLOOKUP(C9,'Dealer Operations'!B:B,'Dealer Operations'!K:K,"Not Found") -> 89 | M9: 8 | N9: 5 | O9: 7 | P9: 2 | Q9: =IF(I9="Loaner Covered",0.85,IF(I9="External Rental",1.3,IF(I9="No Loaner Coverage",1.6,1))) -> 0.85 | R9: =IF(H9<=1,1,IF(H9=2,1.15,IF(H9=3,1.3,1.45))) -> 1.45 | S9: =IF(N9=0,1,IF(N9=1,1.75,IF(N9=2,2.5,IF(N9=3,3.25,4)))) -> 4 | T9: =IF(M9<=1,1,IF(M9<=3,1.75,IF(M9<=5,2.5,IF(M9<=7,3.25,3.75)))) -> 3.75 | U9: =IF(J9>=85,1,IF(J9>=75,1.1,IF(J9>=65,1.25,IF(J9>=55,1.35,1.45)))) -> 1 | V9: =IF(K9<=5,1,IF(K9<=10,1.1,IF(K9<=15,1.3,1.5))) -> 1.1 | W9: =IF(L9>=95,1,IF(L9>=85,1.1,IF(L9>=75,1.2,IF(L9>=65,1.3,1.4)))) -> 1.1 | X9: =IF(G9<=7,1,IF(G9<=14,1.1,IF(G9<=21,1.25,IF(G9<=29,1.5,2)))) -> 1.5 | Y9: =((0.35*Q9)+(0.65*R9))*((0.6*S9)+(0.4*T9)) -> 4.836 | Z9: =(0.35*U9)+(0.45*V9)+(0.2*W9) -> 1.065 | AA9: =Y9*Z9*X9 -> 7.72551 | AB9: =MIN(AA9,15) -> 7.72551 | AC9: =IF(AB9<3,"Low operational exposure",IF(AB9<6,"Moderate friction",IF(AB9<10,"High escalation risk",IF(AB9<12,"Severe exposure","Critical / Executive intervention")))) -> High escalation risk
A10: E79RB7N6W3F2HO43G | B10: 1 | C10: 77841 | D10: =_xlfn.XLOOKUP(C10,'Dealer Operations'!B:B,'Dealer Operations'!C:C,"Not Found") -> Victorville Hyundai | E10: =_xlfn.XLOOKUP(C11,'Dealer Operations'!B:B,'Dealer Operations'!D:D,"Not Found") -> Fred Mercury | F10: =_xlfn.XLOOKUP(A10,'Dealer Operations'!A:A,'Dealer Operations'!E:E,"Not Found") -> 46140 | G10: 15 | H10: 1 | I10: No Loaner Coverage | J10: =_xlfn.XLOOKUP(C10,'Dealer Operations'!B:B,'Dealer Operations'!I:I,"Not Found") -> 86 | K10: =_xlfn.XLOOKUP(C10,'Dealer Operations'!B:B,'Dealer Operations'!J:J,"Not Found") -> 8 | L10: =_xlfn.XLOOKUP(C10,'Dealer Operations'!B:B,'Dealer Operations'!K:K,"Not Found") -> 80 | M10: 7 | N10: 7 | O10: 9 | P10: 1 | Q10: =IF(I10="Loaner Covered",0.85,IF(I10="External Rental",1.3,IF(I10="No Loaner Coverage",1.6,1))) -> 1.6 | R10: =IF(H10<=1,1,IF(H10=2,1.15,IF(H10=3,1.3,1.45))) -> 1 | S10: =IF(N10=0,1,IF(N10=1,1.75,IF(N10=2,2.5,IF(N10=3,3.25,4)))) -> 4 | T10: =IF(M10<=1,1,IF(M10<=3,1.75,IF(M10<=5,2.5,IF(M10<=7,3.25,3.75)))) -> 3.25 | U10: =IF(J10>=85,1,IF(J10>=75,1.1,IF(J10>=65,1.25,IF(J10>=55,1.35,1.45)))) -> 1 | V10: =IF(K10<=5,1,IF(K10<=10,1.1,IF(K10<=15,1.3,1.5))) -> 1.1 | W10: =IF(L10>=95,1,IF(L10>=85,1.1,IF(L10>=75,1.2,IF(L10>=65,1.3,1.4)))) -> 1.2 | X10: =IF(G10<=7,1,IF(G10<=14,1.1,IF(G10<=21,1.25,IF(G10<=29,1.5,2)))) -> 1.25 | Y10: =((0.35*Q10)+(0.65*R10))*((0.6*S10)+(0.4*T10)) -> 4.477 | Z10: =(0.35*U10)+(0.45*V10)+(0.2*W10) -> 1.085 | AA10: =Y10*Z10*X10 -> 6.0719313 | AB10: =MIN(AA10,15) -> 6.0719313 | AC10: =IF(AB10<3,"Low operational exposure",IF(AB10<6,"Moderate friction",IF(AB10<10,"High escalation risk",IF(AB10<12,"Severe exposure","Critical / Executive intervention")))) -> High escalation risk
A11: EP1FRBY1U5LZVUQ48 | B11: 0 | C11: 77841 | D11: =_xlfn.XLOOKUP(C11,'Dealer Operations'!B:B,'Dealer Operations'!C:C,"Not Found") -> Victorville Hyundai | E11: =_xlfn.XLOOKUP(C12,'Dealer Operations'!B:B,'Dealer Operations'!D:D,"Not Found") -> Shohei Ohtani | F11: =_xlfn.XLOOKUP(A11,'Dealer Operations'!A:A,'Dealer Operations'!E:E,"Not Found") -> 46127 | G11: 28 | H11: 4 | I11: No Loaner Coverage | J11: =_xlfn.XLOOKUP(C11,'Dealer Operations'!B:B,'Dealer Operations'!I:I,"Not Found") -> 86 | K11: =_xlfn.XLOOKUP(C11,'Dealer Operations'!B:B,'Dealer Operations'!J:J,"Not Found") -> 8 | L11: =_xlfn.XLOOKUP(C11,'Dealer Operations'!B:B,'Dealer Operations'!K:K,"Not Found") -> 80 | M11: 6 | N11: 3 | O11: 8 | P11: 2 | Q11: =IF(I11="Loaner Covered",0.85,IF(I11="External Rental",1.3,IF(I11="No Loaner Coverage",1.6,1))) -> 1.6 | R11: =IF(H11<=1,1,IF(H11=2,1.15,IF(H11=3,1.3,1.45))) -> 1.45 | S11: =IF(N11=0,1,IF(N11=1,1.75,IF(N11=2,2.5,IF(N11=3,3.25,4)))) -> 3.25 | T11: =IF(M11<=1,1,IF(M11<=3,1.75,IF(M11<=5,2.5,IF(M11<=7,3.25,3.75)))) -> 3.25 | U11: =IF(J11>=85,1,IF(J11>=75,1.1,IF(J11>=65,1.25,IF(J11>=55,1.35,1.45)))) -> 1 | V11: =IF(K11<=5,1,IF(K11<=10,1.1,IF(K11<=15,1.3,1.5))) -> 1.1 | W11: =IF(L11>=95,1,IF(L11>=85,1.1,IF(L11>=75,1.2,IF(L11>=65,1.3,1.4)))) -> 1.2 | X11: =IF(G11<=7,1,IF(G11<=14,1.1,IF(G11<=21,1.25,IF(G11<=29,1.5,2)))) -> 1.5 | Y11: =((0.35*Q11)+(0.65*R11))*((0.6*S11)+(0.4*T11)) -> 4.883125 | Z11: =(0.35*U11)+(0.45*V11)+(0.2*W11) -> 1.085 | AA11: =Y11*Z11*X11 -> 7.9472859 | AB11: =MIN(AA11,15) -> 7.9472859 | AC11: =IF(AB11<3,"Low operational exposure",IF(AB11<6,"Moderate friction",IF(AB11<10,"High escalation risk",IF(AB11<12,"Severe exposure","Critical / Executive intervention")))) -> High escalation risk
A12: 8TFTAT95ZJNG1T2LI | B12: 0 | C12: 81773 | D12: =_xlfn.XLOOKUP(C12,'Dealer Operations'!B:B,'Dealer Operations'!C:C,"Not Found") -> Hyundai San Diego | E12: =_xlfn.XLOOKUP(C13,'Dealer Operations'!B:B,'Dealer Operations'!D:D,"Not Found") -> Shohei Ohtani | F12: =_xlfn.XLOOKUP(A12,'Dealer Operations'!A:A,'Dealer Operations'!E:E,"Not Found") -> 46113 | G12: 42 | H12: 2 | I12: External Rental | J12: =_xlfn.XLOOKUP(C12,'Dealer Operations'!B:B,'Dealer Operations'!I:I,"Not Found") -> 68 | K12: =_xlfn.XLOOKUP(C12,'Dealer Operations'!B:B,'Dealer Operations'!J:J,"Not Found") -> 9.3 | L12: =_xlfn.XLOOKUP(C12,'Dealer Operations'!B:B,'Dealer Operations'!K:K,"Not Found") -> 55 | M12: 10 | N12: 2 | O12: 10 | P12: 4 | Q12: =IF(I12="Loaner Covered",0.85,IF(I12="External Rental",1.3,IF(I12="No Loaner Coverage",1.6,1))) -> 1.3 | R12: =IF(H12<=1,1,IF(H12=2,1.15,IF(H12=3,1.3,1.45))) -> 1.15 | S12: =IF(N12=0,1,IF(N12=1,1.75,IF(N12=2,2.5,IF(N12=3,3.25,4)))) -> 2.5 | T12: =IF(M12<=1,1,IF(M12<=3,1.75,IF(M12<=5,2.5,IF(M12<=7,3.25,3.75)))) -> 3.75 | U12: =IF(J12>=85,1,IF(J12>=75,1.1,IF(J12>=65,1.25,IF(J12>=55,1.35,1.45)))) -> 1.25 | V12: =IF(K12<=5,1,IF(K12<=10,1.1,IF(K12<=15,1.3,1.5))) -> 1.1 | W12: =IF(L12>=95,1,IF(L12>=85,1.1,IF(L12>=75,1.2,IF(L12>=65,1.3,1.4)))) -> 1.4 | X12: =IF(G12<=7,1,IF(G12<=14,1.1,IF(G12<=21,1.25,IF(G12<=29,1.5,2)))) -> 2 | Y12: =((0.35*Q12)+(0.65*R12))*((0.6*S12)+(0.4*T12)) -> 3.6075 | Z12: =(0.35*U12)+(0.45*V12)+(0.2*W12) -> 1.2125 | AA12: =Y12*Z12*X12 -> 8.7481875 | AB12: =MIN(AA12,15) -> 8.7481875 | AC12: =IF(AB12<3,"Low operational exposure",IF(AB12<6,"Moderate friction",IF(AB12<10,"High escalation risk",IF(AB12<12,"Severe exposure","Critical / Executive intervention")))) -> High escalation risk
A13: 0ULHWC6FAD7MFBBYW | B13: 0 | C13: 55102 | D13: =_xlfn.XLOOKUP(C13,'Dealer Operations'!B:B,'Dealer Operations'!C:C,"Not Found") -> Riverside Hyundai | E13: =_xlfn.XLOOKUP(C14,'Dealer Operations'!B:B,'Dealer Operations'!D:D,"Not Found") -> Fred Mercury | F13: =_xlfn.XLOOKUP(A13,'Dealer Operations'!A:A,'Dealer Operations'!E:E,"Not Found") -> 46122 | G13: 33 | H13: 4 | I13: External Rental | J13: =_xlfn.XLOOKUP(C13,'Dealer Operations'!B:B,'Dealer Operations'!I:I,"Not Found") -> 94 | K13: =_xlfn.XLOOKUP(C13,'Dealer Operations'!B:B,'Dealer Operations'!J:J,"Not Found") -> 8.4 | L13: =_xlfn.XLOOKUP(C13,'Dealer Operations'!B:B,'Dealer Operations'!K:K,"Not Found") -> 87 | M13: 10 | N13: 1 | O13: 3 | P13: 2 | Q13: =IF(I13="Loaner Covered",0.85,IF(I13="External Rental",1.3,IF(I13="No Loaner Coverage",1.6,1))) -> 1.3 | R13: =IF(H13<=1,1,IF(H13=2,1.15,IF(H13=3,1.3,1.45))) -> 1.45 | S13: =IF(N13=0,1,IF(N13=1,1.75,IF(N13=2,2.5,IF(N13=3,3.25,4)))) -> 1.75 | T13: =IF(M13<=1,1,IF(M13<=3,1.75,IF(M13<=5,2.5,IF(M13<=7,3.25,3.75)))) -> 3.75 | U13: =IF(J13>=85,1,IF(J13>=75,1.1,IF(J13>=65,1.25,IF(J13>=55,1.35,1.45)))) -> 1 | V13: =IF(K13<=5,1,IF(K13<=10,1.1,IF(K13<=15,1.3,1.5))) -> 1.1 | W13: =IF(L13>=95,1,IF(L13>=85,1.1,IF(L13>=75,1.2,IF(L13>=65,1.3,1.4)))) -> 1.1 | X13: =IF(G13<=7,1,IF(G13<=14,1.1,IF(G13<=21,1.25,IF(G13<=29,1.5,2)))) -> 2 | Y13: =((0.35*Q13)+(0.65*R13))*((0.6*S13)+(0.4*T13)) -> 3.563625 | Z13: =(0.35*U13)+(0.45*V13)+(0.2*W13) -> 1.065 | AA13: =Y13*Z13*X13 -> 7.5905212 | AB13: =MIN(AA13,15) -> 7.5905212 | AC13: =IF(AB13<3,"Low operational exposure",IF(AB13<6,"Moderate friction",IF(AB13<10,"High escalation risk",IF(AB13<12,"Severe exposure","Critical / Executive intervention")))) -> High escalation risk
... A101: 9M3ZWOMBEC0JFD45Y | B101: 0 | C101: 81773 | D101: =_xlfn.XLOOKUP(C101,'Dealer Operations'!B:B,'Dealer Operations'!C:C,"Not Found") -> Hyundai San Diego | E101: =_xlfn.XLOOKUP(C102,'Dealer Operations'!B:B,'Dealer Operations'!D:D,"Not Found") -> 0 | F101: =_xlfn.XLOOKUP(A101,'Dealer Operations'!A:A,'Dealer Operations'!E:E,"Not Found") -> 46106 | G101: 49 | H101: 3 | I101: Loaner Covered | J101: =_xlfn.XLOOKUP(C101,'Dealer Operations'!B:B,'Dealer Operations'!I:I,"Not Found") -> 68 | K101: =_xlfn.XLOOKUP(C101,'Dealer Operations'!B:B,'Dealer Operations'!J:J,"Not Found") -> 9.3 | L101: =_xlfn.XLOOKUP(C101,'Dealer Operations'!B:B,'Dealer Operations'!K:K,"Not Found") -> 55 | M101: 7 | N101: 3 | O101: 10 | P101: 0 | Q101: =IF(I101="Loaner Covered",0.85,IF(I101="External Rental",1.3,IF(I101="No Loaner Coverage",1.6,1))) -> 0.85 | R101: =IF(H101<=1,1,IF(H101=2,1.15,IF(H101=3,1.3,1.45))) -> 1.3 | S101: =IF(N101=0,1,IF(N101=1,1.75,IF(N101=2,2.5,IF(N101=3,3.25,4)))) -> 3.25 | T101: =IF(M101<=1,1,IF(M101<=3,1.75,IF(M101<=5,2.5,IF(M101<=7,3.25,3.75)))) -> 3.25 | U101: =IF(J101>=85,1,IF(J101>=75,1.1,IF(J101>=65,1.25,IF(J101>=55,1.35,1.45)))) -> 1.25 | V101: =IF(K101<=5,1,IF(K101<=10,1.1,IF(K101<=15,1.3,1.5))) -> 1.1 | W101: =IF(L101>=95,1,IF(L101>=85,1.1,IF(L101>=75,1.2,IF(L101>=65,1.3,1.4)))) -> 1.4 | X101: =IF(G101<=7,1,IF(G101<=14,1.1,IF(G101<=21,1.25,IF(G101<=29,1.5,2)))) -> 2 | Y101: =((0.35*Q101)+(0.65*R101))*((0.6*S101)+(0.4*T101)) -> 3.713125 | Z101: =(0.35*U101)+(0.45*V101)+(0.2*W101) -> 1.2125 | AA101: =Y101*Z101*X101 -> 9.0043281 | AB101: =MIN(AA101,15) -> 9.0043281 | AC101: =IF(AB101<3,"Low operational exposure",IF(AB101<6,"Moderate friction",IF(AB101<10,"High escalation risk",IF(AB101<12,"Severe exposure","Critical / Executive intervention")))) -> High escalation risk

Sheet CEO Escalation VINs
A1: VIN | B1: CEO Escalated
A2: K8RGIPX8FOH9FBCO6 | B2: 1
A3: JOAPPZMJI07SH2OHE | B3: 1
A4: E79RB7N6W3F2HO43G | B4: 1
A5: KAG7VX26WWWZVYHYQ | B5: 1
A6: 13WQUI8MW33QKTE4M | B6: 1
A7: JXKUOGFH6RH69QFGD | B7: 1
A8: PG0B3JX9VXLABFWPS | B8: 1
A9: MT7JESIDFBHLK1KSG | B9: 1
A10: UTZSX3SO8HYO1E9MC | B10: 1
A11: KIKQFQJ89TI8LMANR | B11: 1
A12: OL9F0XB46W03FSS42 | B12: 1
A13: 080L5LI6WYX9Q4Z4P | B13: 1
... A21: 18DVWHNFHJVXHALYG | B21: 1

Sheet Dealer Operations
A1: VIN | B1: Dealer Code | C1: Dealer Name | D1: Area Manager | E1: RO Open Date | F1: Days Down | G1: Repeat Repairs | H1: Mobility Status | I1: Dealer NPS | J1: Dealer Repeat Repair % | K1: Dealer Training Completion %
A2: IFDW52OJAXUMXP70I | B2: 44117 | C2: Desert Hyundai | D2: Fred Mercury | E2: =$B$103-Dealer_Operations_Table[[#This Row],[Days Down]] -> 46108 | F2: 47 | G2: 1 | H2: No Loaner Coverage | I2: 58 | J2: 10.5 | K2: 49
A3: 282UKC9Z3LV93VLP5 | B3: 44117 | C3: Desert Hyundai | D3: Fred Mercury | E3: =$B$103-Dealer_Operations_Table[[#This Row],[Days Down]] -> 46111 | F3: 44 | G3: 0 | H3: Loaner Covered | I3: 58 | J3: 10.5 | K3: 49
A4: MT7JESIDFBHLK1KSG | B4: 44117 | C4: Desert Hyundai | D4: Fred Mercury | E4: =$B$103-Dealer_Operations_Table[[#This Row],[Days Down]] -> 46113 | F4: 42 | G4: 5 | H4: No Loaner Coverage | I4: 58 | J4: 10.5 | K4: 49
A5: XHFAAYE8D5EAZI0GB | B5: 44117 | C5: Desert Hyundai | D5: Fred Mercury | E5: =$B$103-Dealer_Operations_Table[[#This Row],[Days Down]] -> 46117 | F5: 38 | G5: 0 | H5: No Loaner Coverage | I5: 58 | J5: 10.5 | K5: 49
A6: 3W3WKDD1HLPAJKZNL | B6: 44117 | C6: Desert Hyundai | D6: Fred Mercury | E6: =$B$103-Dealer_Operations_Table[[#This Row],[Days Down]] -> 46135 | F6: 20 | G6: 4 | H6: No Loaner Coverage | I6: 58 | J6: 10.5 | K6: 49
A7: 51Z4YXQLWDP2ZWJPQ | B7: 44117 | C7: Desert Hyundai | D7: Fred Mercury | E7: =$B$103-Dealer_Operations_Table[[#This Row],[Days Down]] -> 46139 | F7: 16 | G7: 2 | H7: Loaner Covered | I7: 58 | J7: 10.5 | K7: 49
A8: SHSAJDOBAKIVT1XZ5 | B8: 44117 | C8: Desert Hyundai | D8: Fred Mercury | E8: =$B$103-Dealer_Operations_Table[[#This Row],[Days Down]] -> 46144 | F8: 11 | G8: 1 | H8: External Rental | I8: 58 | J8: 10.5 | K8: 49
A9: 1DGB16XN32UJKPLPX | B9: 44117 | C9: Desert Hyundai | D9: Fred Mercury | E9: =$B$103-Dealer_Operations_Table[[#This Row],[Days Down]] -> 46145 | F9: 10 | G9: 3 | H9: Loaner Covered | I9: 58 | J9: 10.5 | K9: 49
A10: UMO59NH0HA6P3O5QF | B10: 44117 | C10: Desert Hyundai | D10: Fred Mercury | E10: =$B$103-Dealer_Operations_Table[[#This Row],[Days Down]] -> 46148 | F10: 7 | G10: 4 | H10: No Loaner Coverage | I10: 58 | J10: 10.5 | K10: 49
A11: 1RG2L28OO80GEF63F | B11: 39018 | C11: Huntington Beach Hyundai | D11: Shohei Ohtani | E11: =$B$103-Dealer_Operations_Table[[#This Row],[Days Down]] -> 46107 | F11: 48 | G11: 5 | H11: Loaner Covered | I11: 73 | J11: 9.9 | K11: 79
A12: KUN0HIIF5ULO9SI3X | B12: 39018 | C12: Huntington Beach Hyundai | D12: Shohei Ohtani | E12: =$B$103-Dealer_Operations_Table[[#This Row],[Days Down]] -> 46110 | F12: 45 | G12: 1 | H12: Loaner Covered | I12: 73 | J12: 9.9 | K12: 79
A13: KIKQFQJ89TI8LMANR | B13: 39018 | C13: Huntington Beach Hyundai | D13: Shohei Ohtani | E13: =$B$103-Dealer_Operations_Table[[#This Row],[Days Down]] -> 46116 | F13: 39 | G13: 5 | H13: External Rental | I13: 73 | J13: 9.9 | K13: 79
... A101: RXCZX93KNYAQGEC1E | B101: 77841 | C101: Victorville Hyundai | D101: Fred Mercury | E101: =$B$103-Dealer_Operations_Table[[#This Row],[Days Down]] -> 46153 | F101: 2 | G101: 0 | H101: External Rental | I101: 86 | J101: 8 | K101: 80
A103: Report Date | B103: 46155

Sheet Call Center Profiles
A1: VIN | B1: Agent Transfers | C1: Missed Callbacks | D1: Inbound Calls | E1: Case Reopens
A2: LFXCTNCSBPCDP3EIW | B2: 3 | C2: 6 | D2: 7 | E2: 2
A3: 8UO9B4KFEL3GUXNTC | B3: 8 | C3: 1 | D3: 8 | E3: 1
A4: CHYPLVQK2ZIUS50K9 | B4: 5 | C4: 0 | D4: 7 | E4: 3
A5: EP1FRBY1U5LZVUQ48 | B5: 6 | C5: 3 | D5: 8 | E5: 2
A6: RXCZX93KNYAQGEC1E | B6: 4 | C6: 0 | D6: 2 | E6: 3
A7: IO5CQT535KOM58FGI | B7: 2 | C7: 6 | D7: 6 | E7: 3
A8: IRVJAPNU8YSWYB625 | B8: 7 | C8: 3 | D8: 4 | E8: 2
A9: 2OODWCCHFMBAFDNA5 | B9: 9 | C9: 2 | D9: 7 | E9: 0
A10: WFJMNE49QRDDMJ3FA | B10: 6 | C10: 2 | D10: 5 | E10: 4
A11: 8TFTAT95ZJNG1T2LI | B11: 10 | C11: 2 | D11: 10 | E11: 4
A12: 394330ISMBBKJY8Q7 | B12: 10 | C12: 3 | D12: 1 | E12: 2
A13: 98NHIHHW64RX2DX62 | B13: 8 | C13: 5 | D13: 5 | E13: 4
... A101: J43Y6MDT2H17IVYQH | B101: 7 | C101: 5 | D101: 7 | E101: 1

Sheet Regression Analytics
A1: Variable | B1: Coefficient | C1: Likelihood Factor (Odds Ratio)
A2: Days Down | B2: 0.163 | C2: 1.18
A3: Repeat Repairs | B3: 1.197 | C3: 3.31
A4: Mobility Disruption | B4: 0.075 | C4: 1.08
A5: Agent Transfers | B5: 1.386 | C5: 4
A6: Missed Callbacks | B6: 1.802 | C6: 6.06
A7: Dealer NPS | B7: -0.057 | C7: 0.94
A8: Dealer Repeat Repair % | B8: 0.152 | C8: 1.16
A9: Dealer Training Completion % | B9: -0.025 | C9: 0.97
A11: Metric | B11: Value
A12: ROC AUC | B12: 0.998
A13: Escalated VINs | B13: 20
A14: Total VINs | B14: 100

Sheet Multiplier Tables
A1: Mobility Disruption
A2: Status | B2: Multiplier
A3: Loaner Covered | B3: 0.85
A4: External Rental | B4: 1.3
A5: No Loaner Coverage | B5: 1.6
A8: Repeat Repair
A9: Count | B9: Multiplier
A10: 0-1 | B10: 1
A11: 2 | B11: 1.15
A12: 3 | B12: 1.3
A13: 4+ | B13: 1.45
A16: Missed Callbacks
A17: Count | B17: Multiplier
A18: 0 | B18: 1
A19: 1 | B19: 1.75
A20: 2 | B20: 2.5
A21: 3 | B21: 3.25
A22: 4+ | B22: 4
A25: Agent Transfers
A26: Count | B26: Multiplier
A27: 0-1 | B27: 1
A28: 2-3 | B28: 1.75
A29: 4-5 | B29: 2.5
A30: 6-7 | B30: 3.25
A31: 8+ | B31: 3.75
A34: Dealer NPS
A35: NPS | B35: Multiplier
A36: 85+ | B36: 1
A37: 75-84 | B37: 1.1
A38: 65-74 | B38: 1.25
A39: 55-64 | B39: 1.35
A40: <55 | B40: 1.45
A43: Dealer Repeat Repair %
A44: Rate | B44: Multiplier
A45: 0-5% | B45: 1
A46: 5.1-10% | B46: 1.1
A47: 10.1-15% | B47: 1.3
A48: 15.1%+ | B48: 1.5
A51: Training Completion %
A52: Completion | B52: Multiplier
...

Sheet Risk Bands
A1: Risk Score Range | B1: Interpretation
A2: 1-3 | B2: Low operational exposure
A3: 3-6 | B3: Moderate friction
A4: 6-9 | B4: High escalation risk
A5: 9-12 | B5: Severe exposure
A6: 12-15 | B6: Critical / Executive intervention

Sheet ML Predictions
A1: VIN | B1: CEO Escalated | C1: ML Escalation Probability | D1: ML Operational Percentile | E1: ML Risk Band
A2: 31BBC7J06MJ8WJZLJ | B2: 1 | C2: 99.57 | D2: 100 | E2: Critical
A3: 39XMTEA8XS7P53HJK | B3: 1 | C3: 99.47 | D3: 99 | E3: Critical
A4: Z0CVN336C567DHEB4 | B4: 1 | C4: 99.4 | D4: 98 | E4: Critical
A5: 18DVWHNFHJVXHALYG | B5: 1 | C5: 99.33 | D5: 97 | E5: Critical
A6: 7TZB0Q1XKB7EQMK09 | B6: 1 | C6: 99.27 | D6: 96 | E6: Critical
A7: 080L5LI6WYX9Q4Z4P | B7: 1 | C7: 98.82 | D7: 95 | E7: Critical
A8: KIKQFQJ89TI8LMANR | B8: 1 | C8: 98.79 | D8: 94 | E8: Critical
A9: KAG7VX26WWWZVYHYQ | B9: 1 | C9: 98.71 | D9: 93 | E9: Critical
A10: 98NHIHHW64RX2DX62 | B10: 1 | C10: 98.66 | D10: 92 | E10: Critical
A11: 13WQUI8MW33QKTE4M | B11: 1 | C11: 98.36 | D11: 91 | E11: Critical
A12: L0F4RCNUPYF2NXWPN | B12: 1 | C12: 97.81 | D12: 90 | E12: Critical
A13: PG0B3JX9VXLABFWPS | B13: 1 | C13: 97.74 | D13: 89 | E13: Severe
... A101: SQQE6H97AQ38QJH8H | B101: 0 | C101: 0.12 | D101: 2 | E101: Low

Sheet ML Feature Importance
A1: Feature | B1: Importance
A2: Dealer Repeat Repair % | B2: 0.18955039
A3: Dealer Training Completion % | B3: 0.17513095
A4: Repeat Repairs | B4: 0.15300523
A5: Missed Callbacks | B5: 0.138648
A6: Dealer NPS | B6: 0.13456426
A7: Agent Transfers | B7: 0.11675995
A8: Mobility Status | B8: 0.035267451
A9: Days Down | B9: 0.0278226
A10: Case Reopens | B10: 0.027066361
A11: CAC Contacts | B11: 0.0021848121

Sheet ML Metrics
A1: Metric | B1: Value
A2: ROC AUC | B2: 0.84
A3: Model Type | B3: Clean Operational Gradient Boosting Prototype
A4: Target Variable | B4: CEO Escalated
A5: Rows Used | B5: 100
A6: Features Used | B6: 10
